Workbook

Sheet 填寫說明
A1: 文化部臺灣手語語料庫｜人工資料校訂表
A3: 項目 | B3: 填寫方式
A4: 本表筆數 | B4: 5125
A5: 評估範圍 | B5: 中文語意，以及 Gloss 的詞彙與語序。
A6: 主審判定 | B6: 每列只選：通過／需更正／排除／需複審。
A7: 通過 | B7: 原始中文與原始 Gloss 可直接作為 Text→Gloss 訓練資料。
A8: 需更正 | B8: 填問題類型、更正 Gloss 與理由；只有中文也需修改時才填更正中文。
A9: 排除 | B9: 填問題類型與理由；該列不會進入訓練資料。
A10: 需複審 | B10: 主審無法確定時選此項，再由第二位評估者填複審欄。
A11: 需影片確認 | B11: NMS、手形或動作方向不確定時選「是」；不阻擋文字層 Text→Gloss 校訂。
A12: 可填區域 | B12: 只填黃色欄 J:S；灰色 A:I 是原始資料，藍色 T:X 由公式產生。
A13: 姓名與日期 | B13: 本表不包含主審姓名、主審日期、複審姓名或複審日期欄位。
A15: 判定範例 | B15: 主審判定 | C15: 問題類型 | D15: 更正中文 | E15: 更正Gloss | F15: 更正理由
A16: 無問題 | B16: 通過
A17: Gloss 語序需修正 | B17: 需更正 | C17: Gloss語序錯誤 | E17: 學校/我/去 | F17: 主題應前置
A18: 資料無法使用 | B18: 排除 | C18: 中文與Gloss不對應 | F18: 無法由現有資訊修正

Sheet 人工校訂
A1: 穩定ID | B1: 重複來源ID | C1: 資料來源 | D1: 來源子類型 | E1: 原始中文 | F1: 原始Gloss | G1: 來源說明 | H1: 影片或文獻連結 | I1: 原始資料指紋 | J1: 主審判定 | K1: 問題類型 | L1: 更正中文 | M1: 更正Gloss | N1: 更正理由 | O1: 需影片確認 | P1: 複審判定 | Q1: 複審更正中文 | R1: 複審更正Gloss | S1: 複審意見 | T1: 最終判定 | U1: 最終中文 | V1: 最終Gloss | W1: 可匯入訓練 | X1: 資料檢查結果
A2: TC00001 | B2: TC00001 | C2: 文化部臺灣手語語料庫 | D2: 公共服務 | E2: 我的朋友半年前突然車禍， | F2: 我/朋友/六個月/以前/突然/車禍 | G2: G2D1P1/a81｜篇章1段落1｜臺灣手語語料庫（測試版），文化部，https://tslcorpus.moc.gov.tw/ | H2: https://tslcorpus.moc.gov.tw/upload/24/web/video/Bphwq023LKHuHx1y.mp4 | I2: 38a9fd017cf4d46acddd066cf0b278cfeb8cc7617defe5fc55d1dd15449bf5da | J2: 通過 | O2: 否 | T2: =IF(J2="","未填",IF(J2="需複審",IF(OR(P2="",P2="仍需複審"),"待複審",P2),J2)) -> 通過 | U2: =IF(T2="通過",E2,IF(T2="需更正",IF(J2="需複審",IF(Q2="",E2,Q2),IF(L2="",E2,L2)),"")) -> 我的朋友半年前突然車禍， | V2: =IF(T2="通過",F2,IF(T2="需更正",IF(J2="需複審",R2,M2),"")) -> 我/朋友/六個月/以前/突然/車禍 | W2: =IF(AND(OR(T2="通過",AND(T2="需更正",V2<>"")),X2="通過"),"是","否") -> 是 | X2: =IF(J2="","未填",IF(AND(J2="需複審",OR(P2="",P2="仍需複審")),"待複審",IF(OR(AND(J2="需更正",K2=""),AND(J2="需更正",M2=""),AND(J2="需更正",N2=""),AND(J2="排除",OR(K2="",N2="")),AND(J2="需複審",P2="需更正",R2=""),AND(J2="需複審",P2="需更正",S2=""),AND(J2="需複審",P2="排除",S2="")),"錯誤：請補齊必填欄位","通過"))) -> 通過
A3: TC00002 | B3: TC00002 | C3: 文化部臺灣手語語料庫 | D3: 公共服務 | E3: 造成雙耳極重度的聽損。 | F3: 雙耳/聽損/程度/重/很 | G3: G2D1P1/a82｜篇章1段落1｜臺灣手語語料庫（測試版），文化部，https://tslcorpus.moc.gov.tw/ | H3: https://tslcorpus.moc.gov.tw/upload/24/web/video/Bphwq023LKHuHx1y.mp4 | I3: 0d7bf9931bb67b32e48b696c05f5bd4e4a11435db9941f8fc5563698d1c894b4 | J3: 通過 | O3: 否 | T3: =IF(J3="","未填",IF(J3="需複審",IF(OR(P3="",P3="仍需複審"),"待複審",P3),J3)) -> 通過 | U3: =IF(T3="通過",E3,IF(T3="需更正",IF(J3="需複審",IF(Q3="",E3,Q3),IF(L3="",E3,L3)),"")) -> 造成雙耳極重度的聽損。 | V3: =IF(T3="通過",F3,IF(T3="需更正",IF(J3="需複審",R3,M3),"")) -> 雙耳/聽損/程度/重/很 | W3: =IF(AND(OR(T3="通過",AND(T3="需更正",V3<>"")),X3="通過"),"是","否") -> 是 | X3: =IF(J3="","未填",IF(AND(J3="需複審",OR(P3="",P3="仍需複審")),"待複審",IF(OR(AND(J3="需更正",K3=""),AND(J3="需更正",M3=""),AND(J3="需更正",N3=""),AND(J3="排除",OR(K3="",N3="")),AND(J3="需複審",P3="需更正",R3=""),AND(J3="需複審",P3="需更正",S3=""),AND(J3="需複審",P3="排除",S3="")),"錯誤：請補齊必填欄位","通過"))) -> 通過
A4: TC00003 | B4: TC00003 | C4: 文化部臺灣手語語料庫 | D4: 公共服務 | E4: 他在醫院治療期間，發現自己無法聽見。 | F4: 他/醫院/治療/期間/發現/自己/聽/沒辦法 | G4: G2D1P1/a83｜篇章1段落1｜臺灣手語語料庫（測試版），文化部，https://tslcorpus.moc.gov.tw/ | H4: https://tslcorpus.moc.gov.tw/upload/24/web/video/Bphwq023LKHuHx1y.mp4 | I4: b4a42ec76a4b5e43fd468dbd60e30e8e39e646cf6cca6fff6108fec272c670c3 | J4: 通過 | O4: 否 | T4: =IF(J4="","未填",IF(J4="需複審",IF(OR(P4="",P4="仍需複審"),"待複審",P4),J4)) -> 通過 | U4: =IF(T4="通過",E4,IF(T4="需更正",IF(J4="需複審",IF(Q4="",E4,Q4),IF(L4="",E4,L4)),"")) -> 他在醫院治療期間，發現自己無法聽見。 | V4: =IF(T4="通過",F4,IF(T4="需更正",IF(J4="需複審",R4,M4),"")) -> 他/醫院/治療/期間/發現/自己/聽/沒辦法 | W4: =IF(AND(OR(T4="通過",AND(T4="需更正",V4<>"")),X4="通過"),"是","否") -> 是 | X4: =IF(J4="","未填",IF(AND(J4="需複審",OR(P4="",P4="仍需複審")),"待複審",IF(OR(AND(J4="需更正",K4=""),AND(J4="需更正",M4=""),AND(J4="需更正",N4=""),AND(J4="排除",OR(K4="",N4="")),AND(J4="需複審",P4="需更正",R4=""),AND(J4="需複審",P4="需更正",S4=""),AND(J4="需複審",P4="排除",S4="")),"錯誤：請補齊必填欄位","通過"))) -> 通過
A5: TC00004 | B5: TC00004 | C5: 文化部臺灣手語語料庫 | D5: 公共服務 | E5: 聽力檢查證實右耳聽力為九十五分貝，左耳九十分貝， | F5: 聽力/檢查/證實/右耳/九十五/左耳/九十 | G5: G2D1P1/a84｜篇章1段落1｜臺灣手語語料庫（測試版），文化部，https://tslcorpus.moc.gov.tw/ | H5: https://tslcorpus.moc.gov.tw/upload/24/web/video/Bphwq023LKHuHx1y.mp4 | I5: c25131587947a4eee8157a680927da8ab424e37a74099cb84441eb3b69aa28d7 | J5: 通過 | O5: 否 | T5: =IF(J5="","未填",IF(J5="需複審",IF(OR(P5="",P5="仍需複審"),"待複審",P5),J5)) -> 通過 | U5: =IF(T5="通過",E5,IF(T5="需更正",IF(J5="需複審",IF(Q5="",E5,Q5),IF(L5="",E5,L5)),"")) -> 聽力檢查證實右耳聽力為九十五分貝，左耳九十分貝， | V5: =IF(T5="通過",F5,IF(T5="需更正",IF(J5="需複審",R5,M5),"")) -> 聽力/檢查/證實/右耳/九十五/左耳/九十 | W5: =IF(AND(OR(T5="通過",AND(T5="需更正",V5<>"")),X5="通過"),"是","否") -> 是 | X5: =IF(J5="","未填",IF(AND(J5="需複審",OR(P5="",P5="仍需複審")),"待複審",IF(OR(AND(J5="需更正",K5=""),AND(J5="需更正",M5=""),AND(J5="需更正",N5=""),AND(J5="排除",OR(K5="",N5="")),AND(J5="需複審",P5="需更正",R5=""),AND(J5="需複審",P5="需更正",S5=""),AND(J5="需複審",P5="排除",S5="")),"錯誤：請補齊必填欄位","通過"))) -> 通過
A6: TC00005 | B6: TC00005 | C6: 文化部臺灣手語語料庫 | D6: 公共服務 | E6: 聽損程度是極重度。 | F6: 聽損/程度/重/很/是 | G6: G2D1P1/a86｜篇章1段落1｜臺灣手語語料庫（測試版），文化部，https://tslcorpus.moc.gov.tw/ | H6: https://tslcorpus.moc.gov.tw/upload/24/web/video/Bphwq023LKHuHx1y.mp4 | I6: 659e6bbe9a81387cb38be58390154b2cbe9700f890b110dee94d4c4cc6427a92 | J6: 通過 | O6: 否 | T6: =IF(J6="","未填",IF(J6="需複審",IF(OR(P6="",P6="仍需複審"),"待複審",P6),J6)) -> 通過 | U6: =IF(T6="通過",E6,IF(T6="需更正",IF(J6="需複審",IF(Q6="",E6,Q6),IF(L6="",E6,L6)),"")) -> 聽損程度是極重度。 | V6: =IF(T6="通過",F6,IF(T6="需更正",IF(J6="需複審",R6,M6),"")) -> 聽損/程度/重/很/是 | W6: =IF(AND(OR(T6="通過",AND(T6="需更正",V6<>"")),X6="通過"),"是","否") -> 是 | X6: =IF(J6="","未填",IF(AND(J6="需複審",OR(P6="",P6="仍需複審")),"待複審",IF(OR(AND(J6="需更正",K6=""),AND(J6="需更正",M6=""),AND(J6="需更正",N6=""),AND(J6="排除",OR(K6="",N6="")),AND(J6="需複審",P6="需更正",R6=""),AND(J6="需複審",P6="需更正",S6=""),AND(J6="需複審",P6="排除",S6="")),"錯誤：請補齊必填欄位","通過"))) -> 通過
A7: TC00006 | B7: TC00006 | C7: 文化部臺灣手語語料庫 | D7: 公共服務 | E7: 他治療三個月之後， 聽損情形依舊無法回復正常。 | F7: 他/治療/三個月/以後/聽損/依舊/聽人/回/沒辦法 | G7: G2D1P1/a87｜篇章1段落1｜臺灣手語語料庫（測試版），文化部，https://tslcorpus.moc.gov.tw/ | H7: https://tslcorpus.moc.gov.tw/upload/24/web/video/Bphwq023LKHuHx1y.mp4 | I7: 1b54157ddd287bf55249e56b116ef60e996919d66ebddd26c634a64483da4b2f | J7: 通過 | O7: 否 | T7: =IF(J7="","未填",IF(J7="需複審",IF(OR(P7="",P7="仍需複審"),"待複審",P7),J7)) -> 通過 | U7: =IF(T7="通過",E7,IF(T7="需更正",IF(J7="需複審",IF(Q7="",E7,Q7),IF(L7="",E7,L7)),"")) -> 他治療三個月之後， 聽損情形依舊無法回復正常。 | V7: =IF(T7="通過",F7,IF(T7="需更正",IF(J7="需複審",R7,M7),"")) -> 他/治療/三個月/以後/聽損/依舊/聽人/回/沒辦法 | W7: =IF(AND(OR(T7="通過",AND(T7="需更正",V7<>"")),X7="通過"),"是","否") -> 是 | X7: =IF(J7="","未填",IF(AND(J7="需複審",OR(P7="",P7="仍需複審")),"待複審",IF(OR(AND(J7="需更正",K7=""),AND(J7="需更正",M7=""),AND(J7="需更正",N7=""),AND(J7="排除",OR(K7="",N7="")),AND(J7="需複審",P7="需更正",R7=""),AND(J7="需複審",P7="需更正",S7=""),AND(J7="需複審",P7="排除",S7="")),"錯誤：請補齊必填欄位","通過"))) -> 通過
A8: TC00007 | B8: TC00007 | C8: 文化部臺灣手語語料庫 | D8: 休閒娛樂 | E8: 新店最近設立了一個陽光運動公園， | F8: 新店/陽光運動公園/最近 | G8: G1D1P1/a93｜篇章1段落1｜臺灣手語語料庫（測試版），文化部，https://tslcorpus.moc.gov.tw/ | H8: https://tslcorpus.moc.gov.tw/upload/24/web/video/US8fgOf7S1DnRtE8.mp4 | I8: e346be912956e7d8da63da416788580d3f0f05bcd3babf8b091af1825fe3e081 | J8: 需更正 | K8: 漏詞 | M8: 新店/陽光運動公園/最近/設立 | N8: 漏詞 | O8: 否 | T8: =IF(J8="","未填",IF(J8="需複審",IF(OR(P8="",P8="仍需複審"),"待複審",P8),J8)) -> 需更正 | U8: =IF(T8="通過",E8,IF(T8="需更正",IF(J8="需複審",IF(Q8="",E8,Q8),IF(L8="",E8,L8)),"")) -> 新店最近設立了一個陽光運動公園， | V8: =IF(T8="通過",F8,IF(T8="需更正",IF(J8="需複審",R8,M8),"")) -> 新店/陽光運動公園/最近/設立 | W8: =IF(AND(OR(T8="通過",AND(T8="需更正",V8<>"")),X8="通過"),"是","否") -> 是 | X8: =IF(J8="","未填",IF(AND(J8="需複審",OR(P8="",P8="仍需複審")),"待複審",IF(OR(AND(J8="需更正",K8=""),AND(J8="需更正",M8=""),AND(J8="需更正",N8=""),AND(J8="排除",OR(K8="",N8="")),AND(J8="需複審",P8="需更正",R8=""),AND(J8="需複審",P8="需更正",S8=""),AND(J8="需複審",P8="排除",S8="")),"錯誤：請補齊必填欄位","通過"))) -> 通過
A9: TC00008 | B9: TC00008 | C9: 文化部臺灣手語語料庫 | D9: 休閒娛樂 | E9: 我以前帶孩子去玩。 | F9: 設立/我/以前/孩子/帶/去/玩 | G9: G1D1P1/a94｜篇章1段落1｜臺灣手語語料庫（測試版），文化部，https://tslcorpus.moc.gov.tw/ | H9: https://tslcorpus.moc.gov.tw/upload/24/web/video/US8fgOf7S1DnRtE8.mp4 | I9: 601b03baf31f1a890a5b56e8427096ca8ff75c895ce5a09a1830d1b04afd08ae | J9: 需更正 | K9: 多餘詞 | M9: 我/以前/孩子/帶/去/玩 | N9: 多詞 | O9: 否 | T9: =IF(J9="","未填",IF(J9="需複審",IF(OR(P9="",P9="仍需複審"),"待複審",P9),J9)) -> 需更正 | U9: =IF(T9="通過",E9,IF(T9="需更正",IF(J9="需複審",IF(Q9="",E9,Q9),IF(L9="",E9,L9)),"")) -> 我以前帶孩子去玩。 | V9: =IF(T9="通過",F9,IF(T9="需更正",IF(J9="需複審",R9,M9),"")) -> 我/以前/孩子/帶/去/玩 | W9: =IF(AND(OR(T9="通過",AND(T9="需更正",V9<>"")),X9="通過"),"是","否") -> 是 | X9: =IF(J9="","未填",IF(AND(J9="需複審",OR(P9="",P9="仍需複審")),"待複審",IF(OR(AND(J9="需更正",K9=""),AND(J9="需更正",M9=""),AND(J9="需更正",N9=""),AND(J9="排除",OR(K9="",N9="")),AND(J9="需複審",P9="需更正",R9=""),AND(J9="需複審",P9="需更正",S9=""),AND(J9="需複審",P9="排除",S9="")),"錯誤：請補齊必填欄位","通過"))) -> 通過
A10: TC00009 | B10: TC00009 | C10: 文化部臺灣手語語料庫 | D10: 休閒娛樂 | E10: 我在公園往四處望去， | F10: 我/環視 | G10: G1D1P1/a95｜篇章1段落1｜臺灣手語語料庫（測試版），文化部，https://tslcorpus.moc.gov.tw/ | H10: https://tslcorpus.moc.gov.tw/upload/24/web/video/US8fgOf7S1DnRtE8.mp4 | I10: 7c8171e086cbe3fdf46328c7d0b2c0467697b7f2cb4e95259be6441866bca49a | J10: 通過 | O10: 否 | T10: =IF(J10="","未填",IF(J10="需複審",IF(OR(P10="",P10="仍需複審"),"待複審",P10),J10)) -> 通過 | U10: =IF(T10="通過",E10,IF(T10="需更正",IF(J10="需複審",IF(Q10="",E10,Q10),IF(L10="",E10,L10)),"")) -> 我在公園往四處望去， | V10: =IF(T10="通過",F10,IF(T10="需更正",IF(J10="需複審",R10,M10),"")) -> 我/環視 | W10: =IF(AND(OR(T10="通過",AND(T10="需更正",V10<>"")),X10="通過"),"是","否") -> 是 | X10: =IF(J10="","未填",IF(AND(J10="需複審",OR(P10="",P10="仍需複審")),"待複審",IF(OR(AND(J10="需更正",K10=""),AND(J10="需更正",M10=""),AND(J10="需更正",N10=""),AND(J10="排除",OR(K10="",N10="")),AND(J10="需複審",P10="需更正",R10=""),AND(J10="需複審",P10="需更正",S10=""),AND(J10="需複審",P10="排除",S10="")),"錯誤：請補齊必填欄位","通過"))) -> 通過
A11: TC00010 | B11: TC00010 | C11: 文化部臺灣手語語料庫 | D11: 休閒娛樂 | E11: 裡面鞦韆、溜滑梯、翹翹板、單槓等遊樂設施， | F11: 鞦韆/溜滑梯/翹翹板/單槓 | G11: G1D1P1/a607｜篇章1段落1｜臺灣手語語料庫（測試版），文化部，https://tslcorpus.moc.gov.tw/ | H11: https://tslcorpus.moc.gov.tw/upload/24/web/video/US8fgOf7S1DnRtE8.mp4 | I11: 71d94903ca749d9d54b7c5a5f23e18c1e954fb4421a3f5201bf840f189fc57f8 | J11: 通過 | O11: 否 | T11: =IF(J11="","未填",IF(J11="需複審",IF(OR(P11="",P11="仍需複審"),"待複審",P11),J11)) -> 通過 | U11: =IF(T11="通過",E11,IF(T11="需更正",IF(J11="需複審",IF(Q11="",E11,Q11),IF(L11="",E11,L11)),"")) -> 裡面鞦韆、溜滑梯、翹翹板、單槓等遊樂設施， | V11: =IF(T11="通過",F11,IF(T11="需更正",IF(J11="需複審",R11,M11),"")) -> 鞦韆/溜滑梯/翹翹板/單槓 | W11: =IF(AND(OR(T11="通過",AND(T11="需更正",V11<>"")),X11="通過"),"是","否") -> 是 | X11: =IF(J11="","未填",IF(AND(J11="需複審",OR(P11="",P11="仍需複審")),"待複審",IF(OR(AND(J11="需更正",K11=""),AND(J11="需更正",M11=""),AND(J11="需更正",N11=""),AND(J11="排除",OR(K11="",N11="")),AND(J11="需複審",P11="需更正",R11=""),AND(J11="需複審",P11="需更正",S11=""),AND(J11="需複審",P11="排除",S11="")),"錯誤：請補齊必填欄位","通過"))) -> 通過
A12: TC00011 | B12: TC00011 | C12: 文化部臺灣手語語料庫 | D12: 休閒娛樂 | E12: 應有盡有。 | F12: 各式各樣/有 | G12: G1D1P1/a608｜篇章1段落1｜臺灣手語語料庫（測試版），文化部，https://tslcorpus.moc.gov.tw/ | H12: https://tslcorpus.moc.gov.tw/upload/24/web/video/US8fgOf7S1DnRtE8.mp4 | I12: 7d22aaf0cb4fb4ef66f075908e3ebc5dc0de7141bc27f6c543e8191001499c94 | J12: 通過 | O12: 否 | T12: =IF(J12="","未填",IF(J12="需複審",IF(OR(P12="",P12="仍需複審"),"待複審",P12),J12)) -> 通過 | U12: =IF(T12="通過",E12,IF(T12="需更正",IF(J12="需複審",IF(Q12="",E12,Q12),IF(L12="",E12,L12)),"")) -> 應有盡有。 | V12: =IF(T12="通過",F12,IF(T12="需更正",IF(J12="需複審",R12,M12),"")) -> 各式各樣/有 | W12: =IF(AND(OR(T12="通過",AND(T12="需更正",V12<>"")),X12="通過"),"是","否") -> 是 | X12: =IF(J12="","未填",IF(AND(J12="需複審",OR(P12="",P12="仍需複審")),"待複審",IF(OR(AND(J12="需更正",K12=""),AND(J12="需更正",M12=""),AND(J12="需更正",N12=""),AND(J12="排除",OR(K12="",N12="")),AND(J12="需複審",P12="需更正",R12=""),AND(J12="需複審",P12="需更正",S12=""),AND(J12="需複審",P12="排除",S12="")),"錯誤：請補齊必填欄位","通過"))) -> 通過
A13: TC00012 | B13: TC00012 | C13: 文化部臺灣手語語料庫 | D13: 休閒娛樂 | E13: 這邊是坡道較短的溜滑梯， | F13: 這/溜滑梯/短 | G13: G1D1P1/a96｜篇章1段落1｜臺灣手語語料庫（測試版），文化部，https://tslcorpus.moc.gov.tw/ | H13: https://tslcorpus.moc.gov.tw/upload/24/web/video/US8fgOf7S1DnRtE8.mp4 | I13: 0e15a0e7b65a7d567f6139251b930006a4624c5efb193f1402799d24af1a4a86 | J13: 通過 | O13: 否 | T13: =IF(J13="","未填",IF(J13="需複審",IF(OR(P13="",P13="仍需複審"),"待複審",P13),J13)) -> 通過 | U13: =IF(T13="通過",E13,IF(T13="需更正",IF(J13="需複審",IF(Q13="",E13,Q13),IF(L13="",E13,L13)),"")) -> 這邊是坡道較短的溜滑梯， | V13: =IF(T13="通過",F13,IF(T13="需更正",IF(J13="需複審",R13,M13),"")) -> 這/溜滑梯/短 | W13: =IF(AND(OR(T13="通過",AND(T13="需更正",V13<>"")),X13="通過"),"是","否") -> 是 | X13: =IF(J13="","未填",IF(AND(J13="需複審",OR(P13="",P13="仍需複審")),"待複審",IF(OR(AND(J13="需更正",K13=""),AND(J13="需更正",M13=""),AND(J13="需更正",N13=""),AND(J13="排除",OR(K13="",N13="")),AND(J13="需複審",P13="需更正",R13=""),AND(J13="需複審",P13="需更正",S13=""),AND(J13="需複審",P13="排除",S13="")),"錯誤：請補齊必填欄位","通過"))) -> 通過
A14: TC00013 | B14: TC00013 | C14: 文化部臺灣手語語料庫 | D14: 休閒娛樂 | E14: 那邊是坡道較長較寬的溜滑梯。 | F14: 那/溜滑梯/長/寬大 | G14: G1D1P1/a609｜篇章1段落1｜臺灣手語語料庫（測試版），文化部，https://tslcorpus.moc.gov.tw/ | H14: https://tslcorpus.moc.gov.tw/upload/24/web/video/US8fgOf7S1DnRtE8.mp4 | I14: 179b2027530b28f066b1bacede3b3ab78e4be7cafe2c0480ca0c897decf4914c | J14: 通過 | O14: 否 | T14: =IF(J14="","未填",IF(J14="需複審",IF(OR(P14="",P14="仍需複審"),"待複審",P14),J14)) -> 通過 | U14: =IF(T14="通過",E14,IF(T14="需更正",IF(J14="需複審",IF(Q14="",E14,Q14),IF(L14="",E14,L14)),"")) -> 那邊是坡道較長較寬的溜滑梯。 | V14: =IF(T14="通過",F14,IF(T14="需更正",IF(J14="需複審",R14,M14),"")) -> 那/溜滑梯/長/寬大 | W14: =IF(AND(OR(T14="通過",AND(T14="需更正",V14<>"")),X14="通過"),"是","否") -> 是 | X14: =IF(J14="","未填",IF(AND(J14="需複審",OR(P14="",P14="仍需複審")),"待複審",IF(OR(AND(J14="需更正",K14=""),AND(J14="需更正",M14=""),AND(J14="需更正",N14=""),AND(J14="排除",OR(K14="",N14="")),AND(J14="需複審",P14="需更正",R14=""),AND(J14="需複審",P14="需更正",S14=""),AND(J14="需複審",P14="排除",S14="")),"錯誤：請補齊必填欄位","通過"))) -> 通過
A15: TC00014 | B15: TC00014 | C15: 文化部臺灣手語語料庫 | D15: 休閒娛樂 | E15: 此外還有一座用繩索編織而成的橋， | F15: 此外/還有/繩子/結繩/橋 | G15: G1D1P1/a97｜篇章1段落1｜臺灣手語語料庫（測試版），文化部，https://tslcorpus.moc.gov.tw/ | H15: https://tslcorpus.moc.gov.tw/upload/24/web/video/US8fgOf7S1DnRtE8.mp4 | I15: da54622c721a73b0854334a38abf4c710eb480d30e401cdcd3c10fd2ac2f1bdb | J15: 通過 | O15: 否 | T15: =IF(J15="","未填",IF(J15="需複審",IF(OR(P15="",P15="仍需複審"),"待複審",P15),J15)) -> 通過 | U15: =IF(T15="通過",E15,IF(T15="需更正",IF(J15="需複審",IF(Q15="",E15,Q15),IF(L15="",E15,L15)),"")) -> 此外還有一座用繩索編織而成的橋， | V15: =IF(T15="通過",F15,IF(T15="需更正",IF(J15="需複審",R15,M15),"")) -> 此外/還有/繩子/結繩/橋 | W15: =IF(AND(OR(T15="通過",AND(T15="需更正",V15<>"")),X15="通過"),"是","否") -> 是 | X15: =IF(J15="","未填",IF(AND(J15="需複審",OR(P15="",P15="仍需複審")),"待複審",IF(OR(AND(J15="需更正",K15=""),AND(J15="需更正",M15=""),AND(J15="需更正",N15=""),AND(J15="排除",OR(K15="",N15="")),AND(J15="需複審",P15="需更正",R15=""),AND(J15="需複審",P15="需更正",S15=""),AND(J15="需複審",P15="排除",S15="")),"錯誤：請補齊必填欄位","通過"))) -> 通過
A16: TC00015 | B16: TC00015 | C16: 文化部臺灣手語語料庫 | D16: 休閒娛樂 | E16: 小孩可以站在橋上雙手扶著繩索往前走。 | F16: 小孩/站上+橋/走+橋/兩邊繩索+扶 | G16: G1D1P1/a98｜篇章1段落1｜臺灣手語語料庫（測試版），文化部，https://tslcorpus.moc.gov.tw/ | H16: https://tslcorpus.moc.gov.tw/upload/24/web/video/US8fgOf7S1DnRtE8.mp4 | I16: d767bbe4f73dae232321336c3534d3cbd0abcfd050d61790090620019fd826e2 | J16: 通過 | O16: 否 | T16: =IF(J16="","未填",IF(J16="需複審",IF(OR(P16="",P16="仍需複審"),"待複審",P16),J16)) -> 通過 | U16: =IF(T16="通過",E16,IF(T16="需更正",IF(J16="需複審",IF(Q16="",E16,Q16),IF(L16="",E16,L16)),"")) -> 小孩可以站在橋上雙手扶著繩索往前走。 | V16: =IF(T16="通過",F16,IF(T16="需更正",IF(J16="需複審",R16,M16),"")) -> 小孩/站上+橋/走+橋/兩邊繩索+扶 | W16: =IF(AND(OR(T16="通過",AND(T16="需更正",V16<>"")),X16="通過"),"是","否") -> 是 | X16: =IF(J16="","未填",IF(AND(J16="需複審",OR(P16="",P16="仍需複審")),"待複審",IF(OR(AND(J16="需更正",K16=""),AND(J16="需更正",M16=""),AND(J16="需更正",N16=""),AND(J16="排除",OR(K16="",N16="")),AND(J16="需複審",P16="需更正",R16=""),AND(J16="需複審",P16="需更正",S16=""),AND(J16="需複審",P16="排除",S16="")),"錯誤：請補齊必填欄位","通過"))) -> 通過
A17: TC00016 | B17: TC00016 | C17: 文化部臺灣手語語料庫 | D17: 休閒娛樂 | E17: 我看到另一頭有個又大又寬的溜冰場， | F17: 我/看/溜冰場/那裡/大/寬大 | G17: G1D1P1/a99｜篇章1段落1｜臺灣手語語料庫（測試版），文化部，https://tslcorpus.moc.gov.tw/ | H17: https://tslcorpus.moc.gov.tw/upload/24/web/video/US8fgOf7S1DnRtE8.mp4 | I17: 7639140eac04acdf524591553cfa78062d51610b7bcea1f5f4c7922a2510569a | J17: 通過 | O17: 否 | T17: =IF(J17="","未填",IF(J17="需複審",IF(OR(P17="",P17="仍需複審"),"待複審",P17),J17)) -> 通過 | U17: =IF(T17="通過",E17,IF(T17="需更正",IF(J17="需複審",IF(Q17="",E17,Q17),IF(L17="",E17,L17)),"")) -> 我看到另一頭有個又大又寬的溜冰場， | V17: =IF(T17="通過",F17,IF(T17="需更正",IF(J17="需複審",R17,M17),"")) -> 我/看/溜冰場/那裡/大/寬大 | W17: =IF(AND(OR(T17="通過",AND(T17="需更正",V17<>"")),X17="通過"),"是","否") -> 是 | X17: =IF(J17="","未填",IF(AND(J17="需複審",OR(P17="",P17="仍需複審")),"待複審",IF(OR(AND(J17="需更正",K17=""),AND(J17="需更正",M17=""),AND(J17="需更正",N17=""),AND(J17="排除",OR(K17="",N17="")),AND(J17="需複審",P17="需更正",R17=""),AND(J17="需複審",P17="需更正",S17=""),AND(J17="需複審",P17="排除",S17="")),"錯誤：請補齊必填欄位","通過"))) -> 通過
A18: TC00017 | B18: TC00017 | C18: 文化部臺灣手語語料庫 | D18: 休閒娛樂 | E18: 溜冰的人很多， | F18: 人/多 | G18: G1D1P1/a100｜篇章1段落1｜臺灣手語語料庫（測試版），文化部，https://tslcorpus.moc.gov.tw/ | H18: https://tslcorpus.moc.gov.tw/upload/24/web/video/US8fgOf7S1DnRtE8.mp4 | I18: 0718741bf09c9984e6da9d98e051d52f3f71bafba86a9c32f89a2d1dcbcf249c | J18: 通過 | O18: 否 | T18: =IF(J18="","未填",IF(J18="需複審",IF(OR(P18="",P18="仍需複審"),"待複審",P18),J18)) -> 通過 | U18: =IF(T18="通過",E18,IF(T18="需更正",IF(J18="需複審",IF(Q18="",E18,Q18),IF(L18="",E18,L18)),"")) -> 溜冰的人很多， | V18: =IF(T18="通過",F18,IF(T18="需更正",IF(J18="需複審",R18,M18),"")) -> 人/多 | W18: =IF(AND(OR(T18="通過",AND(T18="需更正",V18<>"")),X18="通過"),"是","否") -> 是 | X18: =IF(J18="","未填",IF(AND(J18="需複審",OR(P18="",P18="仍需複審")),"待複審",IF(OR(AND(J18="需更正",K18=""),AND(J18="需更正",M18=""),AND(J18="需更正",N18=""),AND(J18="排除",OR(K18="",N18="")),AND(J18="需複審",P18="需更正",R18=""),AND(J18="需複審",P18="需更正",S18=""),AND(J18="需複審",P18="排除",S18="")),"錯誤：請補齊必填欄位","通過"))) -> 通過
A19: TC00018 | B19: TC00018 | C19: 文化部臺灣手語語料庫 | D19: 休閒娛樂 | E19: 但他們都會依序排隊。 | F19: 他們/排隊/按照/會 | G19: G1D1P1/a610｜篇章1段落1｜臺灣手語語料庫（測試版），文化部，https://tslcorpus.moc.gov.tw/ | H19: https://tslcorpus.moc.gov.tw/upload/24/web/video/US8fgOf7S1DnRtE8.mp4 | I19: 41d93ecb86baed358b626ac2a65b4031bd149b56abfd08f51677c53276bf5a77 | J19: 通過 | O19: 否 | T19: =IF(J19="","未填",IF(J19="需複審",IF(OR(P19="",P19="仍需複審"),"待複審",P19),J19)) -> 通過 | U19: =IF(T19="通過",E19,IF(T19="需更正",IF(J19="需複審",IF(Q19="",E19,Q19),IF(L19="",E19,L19)),"")) -> 但他們都會依序排隊。 | V19: =IF(T19="通過",F19,IF(T19="需更正",IF(J19="需複審",R19,M19),"")) -> 他們/排隊/按照/會 | W19: =IF(AND(OR(T19="通過",AND(T19="需更正",V19<>"")),X19="通過"),"是","否") -> 是 | X19: =IF(J19="","未填",IF(AND(J19="需複審",OR(P19="",P19="仍需複審")),"待複審",IF(OR(AND(J19="需更正",K19=""),AND(J19="需更正",M19=""),AND(J19="需更正",N19=""),AND(J19="排除",OR(K19="",N19="")),AND(J19="需複審",P19="需更正",R19=""),AND(J19="需複審",P19="需更正",S19=""),AND(J19="需複審",P19="排除",S19="")),"錯誤：請補齊必填欄位","通過"))) -> 通過
A20: TC00019 | B20: TC00019 | C20: 文化部臺灣手語語料庫 | D20: 身體醫療 | E20: 上星期六我和五六位朋友，一起前往陽明山爬山， | F20: 上週/星期六/朋友/五/六/一起/去/陽明山/爬山 | G20: G2D2P1/a98｜篇章1段落1｜臺灣手語語料庫（測試版），文化部，https://tslcorpus.moc.gov.tw/ | H20: https://tslcorpus.moc.gov.tw/upload/24/web/video/omvqLsk905tqXVMq.mp4 | I20: dbe2fabd5a68d12501b2fe80d5cd1d4b1724a6d0c8491d33a0ed73a26592284d | J20: 通過 | O20: 否 | T20: =IF(J20="","未填",IF(J20="需複審",IF(OR(P20="",P20="仍需複審"),"待複審",P20),J20)) -> 通過 | U20: =IF(T20="通過",E20,IF(T20="需更正",IF(J20="需複審",IF(Q20="",E20,Q20),IF(L20="",E20,L20)),"")) -> 上星期六我和五六位朋友，一起前往陽明山爬山， | V20: =IF(T20="通過",F20,IF(T20="需更正",IF(J20="需複審",R20,M20),"")) -> 上週/星期六/朋友/五/六/一起/去/陽明山/爬山 | W20: =IF(AND(OR(T20="通過",AND(T20="需更正",V20<>"")),X20="通過"),"是","否") -> 是 | X20: =IF(J20="","未填",IF(AND(J20="需複審",OR(P20="",P20="仍需複審")),"待複審",IF(OR(AND(J20="需更正",K20=""),AND(J20="需更正",M20=""),AND(J20="需更正",N20=""),AND(J20="排除",OR(K20="",N20="")),AND(J20="需複審",P20="需更正",R20=""),AND(J20="需複審",P20="需更正",S20=""),AND(J20="需複審",P20="排除",S20="")),"錯誤：請補齊必填欄位","通過"))) -> 通過
A21: TC00020 | B21: TC00020 | C21: 文化部臺灣手語語料庫 | D21: 身體醫療 | E21: 大家一起開心地出遊。 | F21: 我們/開心/出遊 | G21: G2D2P1/a99｜篇章1段落1｜臺灣手語語料庫（測試版），文化部，https://tslcorpus.moc.gov.tw/ | H21: https://tslcorpus.moc.gov.tw/upload/24/web/video/omvqLsk905tqXVMq.mp4 | I21: 394e5ebf49854514b2d468117730841c378bc4c4bcc7ae7f6065f0a4c95834f0 | J21: 通過 | O21: 否 | T21: =IF(J21="","未填",IF(J21="需複審",IF(OR(P21="",P21="仍需複審"),"待複審",P21),J21)) -> 通過 | U21: =IF(T21="通過",E21,IF(T21="需更正",IF(J21="需複審",IF(Q21="",E21,Q21),IF(L21="",E21,L21)),"")) -> 大家一起開心地出遊。 | V21: =IF(T21="通過",F21,IF(T21="需更正",IF(J21="需複審",R21,M21),"")) -> 我們/開心/出遊 | W21: =IF(AND(OR(T21="通過",AND(T21="需更正",V21<>"")),X21="通過"),"是","否") -> 是 | X21: =IF(J21="","未填",IF(AND(J21="需複審",OR(P21="",P21="仍需複審")),"待複審",IF(OR(AND(J21="需更正",K21=""),AND(J21="需更正",M21=""),AND(J21="需更正",N21=""),AND(J21="排除",OR(K21="",N21="")),AND(J21="需複審",P21="需更正",R21=""),AND(J21="需複審",P21="需更正",S21=""),AND(J21="需複審",P21="排除",S21="")),"錯誤：請補齊必填欄位","通過"))) -> 通過
... A52: TC00051 | B52: TC00051 | C52: 文化部臺灣手語語料庫 | D52: 自然環境 | E52: 臺灣的四季， | F52: 臺灣/四季 | G52: G2D4P1/a143｜篇章1段落1｜臺灣手語語料庫（測試版），文化部，https://tslcorpus.moc.gov.tw/ | H52: https://tslcorpus.moc.gov.tw/upload/24/web/video/GztyDxcEDJ2TtmIX.mp4 | I52: e3cad6494a6216c22906f8178456f348d908a8121add1f294bc27b60bf15eaab | J52: 通過 | O52: 否 | T52: =IF(J52="","未填",IF(J52="需複審",IF(OR(P52="",P52="仍需複審"),"待複審",P52),J52)) -> 通過 | U52: =IF(T52="通過",E52,IF(T52="需更正",IF(J52="需複審",IF(Q52="",E52,Q52),IF(L52="",E52,L52)),"")) -> 臺灣的四季， | V52: =IF(T52="通過",F52,IF(T52="需更正",IF(J52="需複審",R52,M52),"")) -> 臺灣/四季 | W52: =IF(AND(OR(T52="通過",AND(T52="需更正",V52<>"")),X52="通過"),"是","否") -> 是 | X52: =IF(J52="","未填",IF(AND(J52="需複審",OR(P52="",P52="仍需複審")),"待複審",IF(OR(AND(J52="需更正",K52=""),AND(J52="需更正",M52=""),AND(J52="需更正",N52=""),AND(J52="排除",OR(K52="",N52="")),AND(J52="需複審",P52="需更正",R52=""),AND(J52="需複審",P52="需更正",S52=""),AND(J52="需複審",P52="排除",S52="")),"錯誤：請補齊必填欄位","通過"))) -> 通過
A53: TC00052 | B53: TC00052 | C53: 文化部臺灣手語語料庫 | D53: 自然環境 | E53: 春天涼爽、夏季炎熱、秋天颳風、冬天寒冷。 | F53: 春季/涼爽/夏季/熱/秋季/風大/冬季/冷 | G53: G2D4P1/a932｜篇章1段落1｜臺灣手語語料庫（測試版），文化部，https://tslcorpus.moc.gov.tw/ | H53: https://tslcorpus.moc.gov.tw/upload/24/web/video/GztyDxcEDJ2TtmIX.mp4 | I53: d6a6c92afd28df74a864f23e20946814f48455adfb02ddf874748e6439cf0757 | J53: 需更正 | K53: 漏詞 | M53: 春季/涼爽/夏季/熱/秋季/風大/冬季/冷/有 | N53: 依文化部語料庫原始標註：補上「有」 | O53: 否 | T53: =IF(J53="","未填",IF(J53="需複審",IF(OR(P53="",P53="仍需複審"),"待複審",P53),J53)) -> 需更正 | U53: =IF(T53="通過",E53,IF(T53="需更正",IF(J53="需複審",IF(Q53="",E53,Q53),IF(L53="",E53,L53)),"")) -> 春天涼爽、夏季炎熱、秋天颳風、冬天寒冷。 | V53: =IF(T53="通過",F53,IF(T53="需更正",IF(J53="需複審",R53,M53),"")) -> 春季/涼爽/夏季/熱/秋季/風大/冬季/冷/有 | W53: =IF(AND(OR(T53="通過",AND(T53="需更正",V53<>"")),X53="通過"),"是","否") -> 是 | X53: =IF(J53="","未填",IF(AND(J53="需複審",OR(P53="",P53="仍需複審")),"待複審",IF(OR(AND(J53="需更正",K53=""),AND(J53="需更正",M53=""),AND(J53="需更正",N53=""),AND(J53="排除",OR(K53="",N53="")),AND(J53="需複審",P53="需更正",R53=""),AND(J53="需複審",P53="需更正",S53=""),AND(J53="需複審",P53="排除",S53="")),"錯誤：請補齊必填欄位","通過"))) -> 通過
A54: TC00053 | B54: TC00053 | C54: 文化部臺灣手語語料庫 | D54: 自然環境 | E54: 現在明明是冬季， 但早晚溫度差異大， | F54: 有/現在/冬季/對/但是/早上/熱+溫度上升/晚上/冷+溫度下降 | G54: G2D4P1/a144｜篇章1段落1｜臺灣手語語料庫（測試版），文化部，https://tslcorpus.moc.gov.tw/ | H54: https://tslcorpus.moc.gov.tw/upload/24/web/video/GztyDxcEDJ2TtmIX.mp4 | I54: e55223cabee153ad807fe18b60239943d78a963fb90e8d7213e0ec76d46502ef | J54: 需更正 | K54: 多餘詞 | M54: 現在/冬季/對/但是/早上/熱+溫度上升/晚上/冷+溫度下降 | N54: 依文化部語料庫原始標註：刪去「有」 | O54: 否 | T54: =IF(J54="","未填",IF(J54="需複審",IF(OR(P54="",P54="仍需複審"),"待複審",P54),J54)) -> 需更正 | U54: =IF(T54="通過",E54,IF(T54="需更正",IF(J54="需複審",IF(Q54="",E54,Q54),IF(L54="",E54,L54)),"")) -> 現在明明是冬季， 但早晚溫度差異大， | V54: =IF(T54="通過",F54,IF(T54="需更正",IF(J54="需複審",R54,M54),"")) -> 現在/冬季/對/但是/早上/熱+溫度上升/晚上/冷+溫度下降 | W54: =IF(AND(OR(T54="通過",AND(T54="需更正",V54<>"")),X54="通過"),"是","否") -> 是 | X54: =IF(J54="","未填",IF(AND(J54="需複審",OR(P54="",P54="仍需複審")),"待複審",IF(OR(AND(J54="需更正",K54=""),AND(J54="需更正",M54=""),AND(J54="需更正",N54=""),AND(J54="排除",OR(K54="",N54="")),AND(J54="需複審",P54="需更正",R54=""),AND(J54="需複審",P54="需更正",S54=""),AND(J54="需複審",P54="排除",S54="")),"錯誤：請補齊必填欄位","通過"))) -> 通過
A55: TC00054 | B55: TC00054 | C55: 文化部臺灣手語語料庫 | D55: 自然環境 | E55: 白天可高達30度， | F55: 白天/曬太陽/熱+溫度上升/三十度 | G55: G2D4P1/a145｜篇章1段落1｜臺灣手語語料庫（測試版），文化部，https://tslcorpus.moc.gov.tw/ | H55: https://tslcorpus.moc.gov.tw/upload/24/web/video/GztyDxcEDJ2TtmIX.mp4 | I55: 9d8a1eb746b3ae47fc37d097c2cc77527f7aa04564ab57fbd75d778b2eaad143 | J55: 通過 | O55: 否 | T55: =IF(J55="","未填",IF(J55="需複審",IF(OR(P55="",P55="仍需複審"),"待複審",P55),J55)) -> 通過 | U55: =IF(T55="通過",E55,IF(T55="需更正",IF(J55="需複審",IF(Q55="",E55,Q55),IF(L55="",E55,L55)),"")) -> 白天可高達30度， | V55: =IF(T55="通過",F55,IF(T55="需更正",IF(J55="需複審",R55,M55),"")) -> 白天/曬太陽/熱+溫度上升/三十度 | W55: =IF(AND(OR(T55="通過",AND(T55="需更正",V55<>"")),X55="通過"),"是","否") -> 是 | X55: =IF(J55="","未填",IF(AND(J55="需複審",OR(P55="",P55="仍需複審")),"待複審",IF(OR(AND(J55="需更正",K55=""),AND(J55="需更正",M55=""),AND(J55="需更正",N55=""),AND(J55="排除",OR(K55="",N55="")),AND(J55="需複審",P55="需更正",R55=""),AND(J55="需複審",P55="需更正",S55=""),AND(J55="需複審",P55="排除",S55="")),"錯誤：請補齊必填欄位","通過"))) -> 通過
A56: TC00055 | B56: TC00055 | C56: 文化部臺灣手語語料庫 | D56: 自然環境 | E56: 晚上也能冷到10度以下。 | F56: 晚上/冷+溫度下降/十+下 | G56: G2D4P1/a146｜篇章1段落1｜臺灣手語語料庫（測試版），文化部，https://tslcorpus.moc.gov.tw/ | H56: https://tslcorpus.moc.gov.tw/upload/24/web/video/GztyDxcEDJ2TtmIX.mp4 | I56: 81f01d0ee4b6a9a24420365bc283a10b23af7647ead7cc718645ff7bbba0983f | J56: 通過 | O56: 否 | T56: =IF(J56="","未填",IF(J56="需複審",IF(OR(P56="",P56="仍需複審"),"待複審",P56),J56)) -> 通過 | U56: =IF(T56="通過",E56,IF(T56="需更正",IF(J56="需複審",IF(Q56="",E56,Q56),IF(L56="",E56,L56)),"")) -> 晚上也能冷到10度以下。 | V56: =IF(T56="通過",F56,IF(T56="需更正",IF(J56="需複審",R56,M56),"")) -> 晚上/冷+溫度下降/十+下 | W56: =IF(AND(OR(T56="通過",AND(T56="需更正",V56<>"")),X56="通過"),"是","否") -> 是 | X56: =IF(J56="","未填",IF(AND(J56="需複審",OR(P56="",P56="仍需複審")),"待複審",IF(OR(AND(J56="需更正",K56=""),AND(J56="需更正",M56=""),AND(J56="需更正",N56=""),AND(J56="排除",OR(K56="",N56="")),AND(J56="需複審",P56="需更正",R56=""),AND(J56="需複審",P56="需更正",S56=""),AND(J56="需複審",P56="排除",S56="")),"錯誤：請補齊必填欄位","通過"))) -> 通過
A57: TC00056 | B57: TC00056 | C57: 文化部臺灣手語語料庫 | D57: 自然環境 | E57: 臺灣的地勢也很特別， | F57: 臺灣/地勢/特別/一樣 | G57: G2D4P1/a147｜篇章1段落1｜臺灣手語語料庫（測試版），文化部，https://tslcorpus.moc.gov.tw/ | H57: https://tslcorpus.moc.gov.tw/upload/24/web/video/GztyDxcEDJ2TtmIX.mp4 | I57: ab2fc9f22f62bf2494e2a05469db02dbecea9c2635c178f575026b2c5297c68f | J57: 通過 | O57: 否 | T57: =IF(J57="","未填",IF(J57="需複審",IF(OR(P57="",P57="仍需複審"),"待複審",P57),J57)) -> 通過 | U57: =IF(T57="通過",E57,IF(T57="需更正",IF(J57="需複審",IF(Q57="",E57,Q57),IF(L57="",E57,L57)),"")) -> 臺灣的地勢也很特別， | V57: =IF(T57="通過",F57,IF(T57="需更正",IF(J57="需複審",R57,M57),"")) -> 臺灣/地勢/特別/一樣 | W57: =IF(AND(OR(T57="通過",AND(T57="需更正",V57<>"")),X57="通過"),"是","否") -> 是 | X57: =IF(J57="","未填",IF(AND(J57="需複審",OR(P57="",P57="仍需複審")),"待複審",IF(OR(AND(J57="需更正",K57=""),AND(J57="需更正",M57=""),AND(J57="需更正",N57=""),AND(J57="排除",OR(K57="",N57="")),AND(J57="需複審",P57="需更正",R57=""),AND(J57="需複審",P57="需更正",S57=""),AND(J57="需複審",P57="排除",S57="")),"錯誤：請補齊必填欄位","通過"))) -> 通過
A58: TC00057 | B58: TC00057 | C58: 文化部臺灣手語語料庫 | D58: 自然環境 | E58: 有很多三千公尺以上的高山， | F58: 臺灣/這/山/高/公尺/三千+上/到處/多 | G58: G2D4P1/a148｜篇章1段落1｜臺灣手語語料庫（測試版），文化部，https://tslcorpus.moc.gov.tw/ | H58: https://tslcorpus.moc.gov.tw/upload/24/web/video/GztyDxcEDJ2TtmIX.mp4 | I58: 1b61c06e5b190a6d15a4ab12264019ed02c020a34f0266bae5bb2ffac22f557b | J58: 通過 | O58: 否 | T58: =IF(J58="","未填",IF(J58="需複審",IF(OR(P58="",P58="仍需複審"),"待複審",P58),J58)) -> 通過 | U58: =IF(T58="通過",E58,IF(T58="需更正",IF(J58="需複審",IF(Q58="",E58,Q58),IF(L58="",E58,L58)),"")) -> 有很多三千公尺以上的高山， | V58: =IF(T58="通過",F58,IF(T58="需更正",IF(J58="需複審",R58,M58),"")) -> 臺灣/這/山/高/公尺/三千+上/到處/多 | W58: =IF(AND(OR(T58="通過",AND(T58="需更正",V58<>"")),X58="通過"),"是","否") -> 是 | X58: =IF(J58="","未填",IF(AND(J58="需複審",OR(P58="",P58="仍需複審")),"待複審",IF(OR(AND(J58="需更正",K58=""),AND(J58="需更正",M58=""),AND(J58="需更正",N58=""),AND(J58="排除",OR(K58="",N58="")),AND(J58="需複審",P58="需更正",R58=""),AND(J58="需複審",P58="需更正",S58=""),AND(J58="需複審",P58="排除",S58="")),"錯誤：請補齊必填欄位","通過"))) -> 通過
A59: TC00058 | B59: TC00058 | C59: 文化部臺灣手語語料庫 | D59: 自然環境 | E59: 還有那美麗蜿蜒崎嶇的海岸線。 | F59: 再/海岸/蜿蜒/看 | G59: G2D4P1/a149｜篇章1段落1｜臺灣手語語料庫（測試版），文化部，https://tslcorpus.moc.gov.tw/ | H59: https://tslcorpus.moc.gov.tw/upload/24/web/video/GztyDxcEDJ2TtmIX.mp4 | I59: 7f7e15026f5d3d58590d801fee19bfc4f531398a48670cb58d2dd9bc7ab55d79 | J59: 需更正 | K59: 漏詞 | M59: 再/海岸/蜿蜒/看/漂亮 | N59: 漏詞 | O59: 否 | T59: =IF(J59="","未填",IF(J59="需複審",IF(OR(P59="",P59="仍需複審"),"待複審",P59),J59)) -> 需更正 | U59: =IF(T59="通過",E59,IF(T59="需更正",IF(J59="需複審",IF(Q59="",E59,Q59),IF(L59="",E59,L59)),"")) -> 還有那美麗蜿蜒崎嶇的海岸線。 | V59: =IF(T59="通過",F59,IF(T59="需更正",IF(J59="需複審",R59,M59),"")) -> 再/海岸/蜿蜒/看/漂亮 | W59: =IF(AND(OR(T59="通過",AND(T59="需更正",V59<>"")),X59="通過"),"是","否") -> 是 | X59: =IF(J59="","未填",IF(AND(J59="需複審",OR(P59="",P59="仍需複審")),"待複審",IF(OR(AND(J59="需更正",K59=""),AND(J59="需更正",M59=""),AND(J59="需更正",N59=""),AND(J59="排除",OR(K59="",N59="")),AND(J59="需複審",P59="需更正",R59=""),AND(J59="需複審",P59="需更正",S59=""),AND(J59="需複審",P59="排除",S59="")),"錯誤：請補齊必填欄位","通過"))) -> 通過
A60: TC00059 | B60: TC00059 | C60: 文化部臺灣手語語料庫 | D60: 自然環境 | E60: 如果想要爬山， | F60: 漂亮/如果/去/登山/要 | G60: G2D4P1/a150｜篇章1段落1｜臺灣手語語料庫（測試版），文化部，https://tslcorpus.moc.gov.tw/ | H60: https://tslcorpus.moc.gov.tw/upload/24/web/video/GztyDxcEDJ2TtmIX.mp4 | I60: 96da4dbcaebc960076532a725729ddac3a75105ec6cead8ad4eec57c37c538e6 | J60: 需更正 | K60: 多餘詞 | M60: 如果/去/登山/要 | N60: 多餘詞 | O60: 否 | T60: =IF(J60="","未填",IF(J60="需複審",IF(OR(P60="",P60="仍需複審"),"待複審",P60),J60)) -> 需更正 | U60: =IF(T60="通過",E60,IF(T60="需更正",IF(J60="需複審",IF(Q60="",E60,Q60),IF(L60="",E60,L60)),"")) -> 如果想要爬山， | V60: =IF(T60="通過",F60,IF(T60="需更正",IF(J60="需複審",R60,M60),"")) -> 如果/去/登山/要 | W60: =IF(AND(OR(T60="通過",AND(T60="需更正",V60<>"")),X60="通過"),"是","否") -> 是 | X60: =IF(J60="","未填",IF(AND(J60="需複審",OR(P60="",P60="仍需複審")),"待複審",IF(OR(AND(J60="需更正",K60=""),AND(J60="需更正",M60=""),AND(J60="需更正",N60=""),AND(J60="排除",OR(K60="",N60="")),AND(J60="需複審",P60="需更正",R60=""),AND(J60="需複審",P60="需更正",S60=""),AND(J60="需複審",P60="排除",S60="")),"錯誤：請補齊必填欄位","通過"))) -> 通過
A61: TC00060 | B61: TC00060 | C61: 文化部臺灣手語語料庫 | D61: 自然環境 | E61: 驅車前往三、四個小時一下子就到； | F61: 車子/開車/三小時/四小時 | G61: G2D4P1/a151｜篇章1段落1｜臺灣手語語料庫（測試版），文化部，https://tslcorpus.moc.gov.tw/ | H61: https://tslcorpus.moc.gov.tw/upload/24/web/video/GztyDxcEDJ2TtmIX.mp4 | I61: 6c1e50e8b75ebf0ac266151c89bbd11fd7eb010510d958b4aa8b97edfdb016b5 | J61: 需更正 | K61: 漏詞 | M61: 車子/開車/三小時/四小時/一下子 | N61: 漏詞 | O61: 否 | T61: =IF(J61="","未填",IF(J61="需複審",IF(OR(P61="",P61="仍需複審"),"待複審",P61),J61)) -> 需更正 | U61: =IF(T61="通過",E61,IF(T61="需更正",IF(J61="需複審",IF(Q61="",E61,Q61),IF(L61="",E61,L61)),"")) -> 驅車前往三、四個小時一下子就到； | V61: =IF(T61="通過",F61,IF(T61="需更正",IF(J61="需複審",R61,M61),"")) -> 車子/開車/三小時/四小時/一下子 | W61: =IF(AND(OR(T61="通過",AND(T61="需更正",V61<>"")),X61="通過"),"是","否") -> 是 | X61: =IF(J61="","未填",IF(AND(J61="需複審",OR(P61="",P61="仍需複審")),"待複審",IF(OR(AND(J61="需更正",K61=""),AND(J61="需更正",M61=""),AND(J61="需更正",N61=""),AND(J61="排除",OR(K61="",N61="")),AND(J61="需複審",P61="需更正",R61=""),AND(J61="需複審",P61="需更正",S61=""),AND(J61="需複審",P61="排除",S61="")),"錯誤：請補齊必填欄位","通過"))) -> 通過
A62: TC00061 | B62: TC00061 | C62: 文化部臺灣手語語料庫 | D62: 自然環境 | E62: 如果想要去海邊游泳， | F62: 一下子/如果/去/海邊/海邊+游泳/要 | G62: G2D4P1/a152｜篇章1段落1｜臺灣手語語料庫（測試版），文化部，https://tslcorpus.moc.gov.tw/ | H62: https://tslcorpus.moc.gov.tw/upload/24/web/video/GztyDxcEDJ2TtmIX.mp4 | I62: a2dccd74e107509f990bf801117556f411a6d88de3b8f2968819cf3baf69a2a8 | J62: 需更正 | K62: 多餘詞 | M62: 如果/去/海邊/海邊+游泳/要 | N62: 多餘詞 | O62: 否 | T62: =IF(J62="","未填",IF(J62="需複審",IF(OR(P62="",P62="仍需複審"),"待複審",P62),J62)) -> 需更正 | U62: =IF(T62="通過",E62,IF(T62="需更正",IF(J62="需複審",IF(Q62="",E62,Q62),IF(L62="",E62,L62)),"")) -> 如果想要去海邊游泳， | V62: =IF(T62="通過",F62,IF(T62="需更正",IF(J62="需複審",R62,M62),"")) -> 如果/去/海邊/海邊+游泳/要 | W62: =IF(AND(OR(T62="通過",AND(T62="需更正",V62<>"")),X62="通過"),"是","否") -> 是 | X62: =IF(J62="","未填",IF(AND(J62="需複審",OR(P62="",P62="仍需複審")),"待複審",IF(OR(AND(J62="需更正",K62=""),AND(J62="需更正",M62=""),AND(J62="需更正",N62=""),AND(J62="排除",OR(K62="",N62="")),AND(J62="需複審",P62="需更正",R62=""),AND(J62="需複審",P62="需更正",S62=""),AND(J62="需複審",P62="排除",S62="")),"錯誤：請補齊必填欄位","通過"))) -> 通過
A63: TC00062 | B63: TC00062 | C63: 文化部臺灣手語語料庫 | D63: 自然環境 | E63: 也是一下子就到了。 | F63: 去/一下子 | G63: G2D4P1/a153｜篇章1段落1｜臺灣手語語料庫（測試版），文化部，https://tslcorpus.moc.gov.tw/ | H63: https://tslcorpus.moc.gov.tw/upload/24/web/video/GztyDxcEDJ2TtmIX.mp4 | I63: 990c41990a499ef6a020511860ee4796e32c297ba33d7000f70c5d3b2487fae9 | J63: 需更正 | K63: 漏詞 | M63: 去/一下子/一樣 | N63: 漏詞 | O63: 否 | T63: =IF(J63="","未填",IF(J63="需複審",IF(OR(P63="",P63="仍需複審"),"待複審",P63),J63)) -> 需更正 | U63: =IF(T63="通過",E63,IF(T63="需更正",IF(J63="需複審",IF(Q63="",E63,Q63),IF(L63="",E63,L63)),"")) -> 也是一下子就到了。 | V63: =IF(T63="通過",F63,IF(T63="需更正",IF(J63="需複審",R63,M63),"")) -> 去/一下子/一樣 | W63: =IF(AND(OR(T63="通過",AND(T63="需更正",V63<>"")),X63="通過"),"是","否") -> 是 | X63: =IF(J63="","未填",IF(AND(J63="需複審",OR(P63="",P63="仍需複審")),"待複審",IF(OR(AND(J63="需更正",K63=""),AND(J63="需更正",M63=""),AND(J63="需更正",N63=""),AND(J63="排除",OR(K63="",N63="")),AND(J63="需複審",P63="需更正",R63=""),AND(J63="需複審",P63="需更正",S63=""),AND(J63="需複審",P63="排除",S63="")),"錯誤：請補齊必填欄位","通過"))) -> 通過
A64: TC00063 | B64: TC00063 | C64: 文化部臺灣手語語料庫 | D64: 自然環境 | E64: 有可能早上去登山完， | F64: 一樣/可能/早上/去/登山/完 | G64: G2D4P1/a154｜篇章1段落1｜臺灣手語語料庫（測試版），文化部，https://tslcorpus.moc.gov.tw/ | H64: https://tslcorpus.moc.gov.tw/upload/24/web/video/GztyDxcEDJ2TtmIX.mp4 | I64: 1c6d8de6c44d0acddba8080d4455497577f02f14d09d2b56a51adad4b4db0e9a | J64: 需更正 | K64: 多餘詞 | M64: 可能/早上/去/登山/完 | N64: 多餘詞 | O64: 否 | T64: =IF(J64="","未填",IF(J64="需複審",IF(OR(P64="",P64="仍需複審"),"待複審",P64),J64)) -> 需更正 | U64: =IF(T64="通過",E64,IF(T64="需更正",IF(J64="需複審",IF(Q64="",E64,Q64),IF(L64="",E64,L64)),"")) -> 有可能早上去登山完， | V64: =IF(T64="通過",F64,IF(T64="需更正",IF(J64="需複審",R64,M64),"")) -> 可能/早上/去/登山/完 | W64: =IF(AND(OR(T64="通過",AND(T64="需更正",V64<>"")),X64="通過"),"是","否") -> 是 | X64: =IF(J64="","未填",IF(AND(J64="需複審",OR(P64="",P64="仍需複審")),"待複審",IF(OR(AND(J64="需更正",K64=""),AND(J64="需更正",M64=""),AND(J64="需更正",N64=""),AND(J64="排除",OR(K64="",N64="")),AND(J64="需複審",P64="需更正",R64=""),AND(J64="需複審",P64="需更正",S64=""),AND(J64="需複審",P64="排除",S64="")),"錯誤：請補齊必填欄位","通過"))) -> 通過
A65: TC00064 | B65: TC00064 | C65: 文化部臺灣手語語料庫 | D65: 自然環境 | E65: 下午就去海邊自由自在的游泳。 | F65: 下午/去/海邊/海邊+游泳/自由/悠閒 | G65: G2D4P1/a155｜篇章1段落1｜臺灣手語語料庫（測試版），文化部，https://tslcorpus.moc.gov.tw/ | H65: https://tslcorpus.moc.gov.tw/upload/24/web/video/GztyDxcEDJ2TtmIX.mp4 | I65: 2def2aa277c130d5524564d2db49e691b8ed184daed3e0ef9b18dea9365e8b93 | J65: 通過 | O65: 否 | T65: =IF(J65="","未填",IF(J65="需複審",IF(OR(P65="",P65="仍需複審"),"待複審",P65),J65)) -> 通過 | U65: =IF(T65="通過",E65,IF(T65="需更正",IF(J65="需複審",IF(Q65="",E65,Q65),IF(L65="",E65,L65)),"")) -> 下午就去海邊自由自在的游泳。 | V65: =IF(T65="通過",F65,IF(T65="需更正",IF(J65="需複審",R65,M65),"")) -> 下午/去/海邊/海邊+游泳/自由/悠閒 | W65: =IF(AND(OR(T65="通過",AND(T65="需更正",V65<>"")),X65="通過"),"是","否") -> 是 | X65: =IF(J65="","未填",IF(AND(J65="需複審",OR(P65="",P65="仍需複審")),"待複審",IF(OR(AND(J65="需更正",K65=""),AND(J65="需更正",M65=""),AND(J65="需更正",N65=""),AND(J65="排除",OR(K65="",N65="")),AND(J65="需複審",P65="需更正",R65=""),AND(J65="需複審",P65="需更正",S65=""),AND(J65="需複審",P65="排除",S65="")),"錯誤：請補齊必填欄位","通過"))) -> 通過
A66: TC00065 | B66: TC00065 | C66: 文化部臺灣手語語料庫 | D66: 日常起居 | E66: 我老家在台中， | F66: 我/老家/臺中 | G66: G4D2P1/a139｜篇章1段落1｜臺灣手語語料庫（測試版），文化部，https://tslcorpus.moc.gov.tw/ | H66: https://tslcorpus.moc.gov.tw/upload/24/web/video/LJhgFLDWoNQPbQHZ.mp4 | I66: dc92d6421de0ffb80a51dba9972c9ed69d56fc0faafa62e56c04d0724c1764ba | J66: 通過 | O66: 否 | T66: =IF(J66="","未填",IF(J66="需複審",IF(OR(P66="",P66="仍需複審"),"待複審",P66),J66)) -> 通過 | U66: =IF(T66="通過",E66,IF(T66="需更正",IF(J66="需複審",IF(Q66="",E66,Q66),IF(L66="",E66,L66)),"")) -> 我老家在台中， | V66: =IF(T66="通過",F66,IF(T66="需更正",IF(J66="需複審",R66,M66),"")) -> 我/老家/臺中 | W66: =IF(AND(OR(T66="通過",AND(T66="需更正",V66<>"")),X66="通過"),"是","否") -> 是 | X66: =IF(J66="","未填",IF(AND(J66="需複審",OR(P66="",P66="仍需複審")),"待複審",IF(OR(AND(J66="需更正",K66=""),AND(J66="需更正",M66=""),AND(J66="需更正",N66=""),AND(J66="排除",OR(K66="",N66="")),AND(J66="需複審",P66="需更正",R66=""),AND(J66="需複審",P66="需更正",S66=""),AND(J66="需複審",P66="排除",S66="")),"錯誤：請補齊必填欄位","通過"))) -> 通過
A67: TC00066 | B67: TC00066 | C67: 文化部臺灣手語語料庫 | D67: 日常起居 | E67: 嫁到雲林後懷孕， | F67: 嫁過去/雲林/之後/懷孕 | G67: G4D2P1/a140｜篇章1段落1｜臺灣手語語料庫（測試版），文化部，https://tslcorpus.moc.gov.tw/ | H67: https://tslcorpus.moc.gov.tw/upload/24/web/video/LJhgFLDWoNQPbQHZ.mp4 | I67: a78459394dcbdb81c5c419ee281180bb70db4839fdfdcbb7e526612e06fa9728 | J67: 通過 | O67: 否 | T67: =IF(J67="","未填",IF(J67="需複審",IF(OR(P67="",P67="仍需複審"),"待複審",P67),J67)) -> 通過 | U67: =IF(T67="通過",E67,IF(T67="需更正",IF(J67="需複審",IF(Q67="",E67,Q67),IF(L67="",E67,L67)),"")) -> 嫁到雲林後懷孕， | V67: =IF(T67="通過",F67,IF(T67="需更正",IF(J67="需複審",R67,M67),"")) -> 嫁過去/雲林/之後/懷孕 | W67: =IF(AND(OR(T67="通過",AND(T67="需更正",V67<>"")),X67="通過"),"是","否") -> 是 | X67: =IF(J67="","未填",IF(AND(J67="需複審",OR(P67="",P67="仍需複審")),"待複審",IF(OR(AND(J67="需更正",K67=""),AND(J67="需更正",M67=""),AND(J67="需更正",N67=""),AND(J67="排除",OR(K67="",N67="")),AND(J67="需複審",P67="需更正",R67=""),AND(J67="需複審",P67="需更正",S67=""),AND(J67="需複審",P67="排除",S67="")),"錯誤：請補齊必填欄位","通過"))) -> 通過
A68: TC00067 | B68: TC00067 | C68: 文化部臺灣手語語料庫 | D68: 日常起居 | E68: 接著小孩出生要照顧小孩， | F68: 小孩/出生/照顧 | G68: G4D2P1/a141｜篇章1段落1｜臺灣手語語料庫（測試版），文化部，https://tslcorpus.moc.gov.tw/ | H68: https://tslcorpus.moc.gov.tw/upload/24/web/video/LJhgFLDWoNQPbQHZ.mp4 | I68: 0be7baade92d57fe2d37e1d9f6968d6160d013421bdfadd496aa76423383e330 | J68: 通過 | O68: 否 | T68: =IF(J68="","未填",IF(J68="需複審",IF(OR(P68="",P68="仍需複審"),"待複審",P68),J68)) -> 通過 | U68: =IF(T68="通過",E68,IF(T68="需更正",IF(J68="需複審",IF(Q68="",E68,Q68),IF(L68="",E68,L68)),"")) -> 接著小孩出生要照顧小孩， | V68: =IF(T68="通過",F68,IF(T68="需更正",IF(J68="需複審",R68,M68),"")) -> 小孩/出生/照顧 | W68: =IF(AND(OR(T68="通過",AND(T68="需更正",V68<>"")),X68="通過"),"是","否") -> 是 | X68: =IF(J68="","未填",IF(AND(J68="需複審",OR(P68="",P68="仍需複審")),"待複審",IF(OR(AND(J68="需更正",K68=""),AND(J68="需更正",M68=""),AND(J68="需更正",N68=""),AND(J68="排除",OR(K68="",N68="")),AND(J68="需複審",P68="需更正",R68=""),AND(J68="需複審",P68="需更正",S68=""),AND(J68="需複審",P68="排除",S68="")),"錯誤：請補齊必填欄位","通過"))) -> 通過
A69: TC00068 | B69: TC00068 | C69: 文化部臺灣手語語料庫 | D69: 日常起居 | E69: 所以沒辦法工作， | F69: 工作 | G69: G4D2P1/a142｜篇章1段落1｜臺灣手語語料庫（測試版），文化部，https://tslcorpus.moc.gov.tw/ | H69: https://tslcorpus.moc.gov.tw/upload/24/web/video/LJhgFLDWoNQPbQHZ.mp4 | I69: 5818d19448ad5eb53e403ad94320f465e6bdaf2b397aa1dfdf45b70b2cb197f9 | J69: 需更正 | K69: 漏詞 | M69: 工作/沒辦法 | N69: 漏詞 | O69: 否 | T69: =IF(J69="","未填",IF(J69="需複審",IF(OR(P69="",P69="仍需複審"),"待複審",P69),J69)) -> 需更正 | U69: =IF(T69="通過",E69,IF(T69="需更正",IF(J69="需複審",IF(Q69="",E69,Q69),IF(L69="",E69,L69)),"")) -> 所以沒辦法工作， | V69: =IF(T69="通過",F69,IF(T69="需更正",IF(J69="需複審",R69,M69),"")) -> 工作/沒辦法 | W69: =IF(AND(OR(T69="通過",AND(T69="需更正",V69<>"")),X69="通過"),"是","否") -> 是 | X69: =IF(J69="","未填",IF(AND(J69="需複審",OR(P69="",P69="仍需複審")),"待複審",IF(OR(AND(J69="需更正",K69=""),AND(J69="需更正",M69=""),AND(J69="需更正",N69=""),AND(J69="排除",OR(K69="",N69="")),AND(J69="需複審",P69="需更正",R69=""),AND(J69="需複審",P69="需更正",S69=""),AND(J69="需複審",P69="排除",S69="")),"錯誤：請補齊必填欄位","通過"))) -> 通過
A70: TC00069 | B70: TC00069 | C70: 文化部臺灣手語語料庫 | D70: 日常起居 | E70: 等小孩三歲上幼兒園才開始找工作。 | F70: 沒辦法/等/小孩/長大/三歲/幼兒園/丟/之後/工作/找 | G70: G4D2P1/a143｜篇章1段落1｜臺灣手語語料庫（測試版），文化部，https://tslcorpus.moc.gov.tw/ | H70: https://tslcorpus.moc.gov.tw/upload/24/web/video/LJhgFLDWoNQPbQHZ.mp4 | I70: cf241d5b96e0b56fbe3129f71ebeea737d28155898531f9de8740ac62f4ee928 | J70: 需更正 | K70: 多餘詞 | M70: 等/小孩/長大/三歲/幼兒園/丟/之後/工作/找 | N70: 多餘詞 | O70: 否 | T70: =IF(J70="","未填",IF(J70="需複審",IF(OR(P70="",P70="仍需複審"),"待複審",P70),J70)) -> 需更正 | U70: =IF(T70="通過",E70,IF(T70="需更正",IF(J70="需複審",IF(Q70="",E70,Q70),IF(L70="",E70,L70)),"")) -> 等小孩三歲上幼兒園才開始找工作。 | V70: =IF(T70="通過",F70,IF(T70="需更正",IF(J70="需複審",R70,M70),"")) -> 等/小孩/長大/三歲/幼兒園/丟/之後/工作/找 | W70: =IF(AND(OR(T70="通過",AND(T70="需更正",V70<>"")),X70="通過"),"是","否") -> 是 | X70: =IF(J70="","未填",IF(AND(J70="需複審",OR(P70="",P70="仍需複審")),"待複審",IF(OR(AND(J70="需更正",K70=""),AND(J70="需更正",M70=""),AND(J70="需更正",N70=""),AND(J70="排除",OR(K70="",N70="")),AND(J70="需複審",P70="需更正",R70=""),AND(J70="需複審",P70="需更正",S70=""),AND(J70="需複審",P70="排除",S70="")),"錯誤：請補齊必填欄位","通過"))) -> 通過
...

Sheet 進度統計
A1: 文化部臺灣手語語料庫｜校訂進度
A3: 指標 | B3: 數量
A4: 總筆數 | B4: =COUNTA(人工校訂!$A$2:$A$5126) -> 5125
A5: 未填 | B5: =COUNTIF(人工校訂!$T$2:$T$5126,"未填") -> 0
A6: 通過 | B6: =COUNTIF(人工校訂!$T$2:$T$5126,"通過") -> 4580
A7: 需更正 | B7: =COUNTIF(人工校訂!$T$2:$T$5126,"需更正") -> 527
A8: 排除 | B8: =COUNTIF(人工校訂!$T$2:$T$5126,"排除") -> 18
A9: 待複審 | B9: =COUNTIF(人工校訂!$T$2:$T$5126,"待複審") -> 0
A10: 可匯入訓練 | B10: =COUNTIF(人工校訂!$W$2:$W$5126,"是") -> 5107
A11: 需影片確認 | B11: =COUNTIF(人工校訂!$O$2:$O$5126,"是") -> 0
A12: 資料檢查錯誤 | B12: =COUNTIF(人工校訂!$X$2:$X$5126,"錯誤*") -> 0
A14: 使用提示
A15: 進度會依「人工校訂」中的判定自動更新。
A16: 只有「可匯入訓練＝是」且「資料檢查結果＝通過」的列，才適合日後轉為訓練資料。

Sheet 欄位選項
A1: 主審判定 | B1: 複審判定 | C1: 問題類型 | D1: 需影片確認
A2: 通過 | B2: 通過 | C2: 中文語意錯誤 | D2: 否
A3: 需更正 | B3: 需更正 | C3: Gloss詞彙錯誤 | D3: 是
A4: 排除 | B4: 排除 | C4: Gloss語序錯誤
A5: 需複審 | B5: 仍需複審 | C5: 漏詞
C6: 多餘詞
C7: 拼寫或格式問題
C8: 中文與Gloss不對應
C9: 重複或資料衝突
C10: 需影片或上下文確認
C11: 其他
